I'm sorry, but an uncaught exception occurred.

While running game code:
  File "renpy/common/00start.rpy", line 226, in script call
    call _splashscreen from _call_splashscreen_1
  File "game/script.rpy", line 142, in script call
    call ch03_main
  File "game/script.rpy", line 303, in script
    if dic["ch03_1plyr"] == "positive":
  File "game/script.rpy", line 303, in <module>
    if dic["ch03_1plyr"] == "positive":
KeyError: u'ch03_1plyr'

-- Full Traceback ------------------------------------------------------------

Full traceback:
  File "renpy/common/00start.rpy", line 226, in script call
    call _splashscreen from _call_splashscreen_1
  File "game/script.rpy", line 142, in script call
    call ch03_main
  File "game/script.rpy", line 303, in script
    if dic["ch03_1plyr"] == "positive":
  File "C:\Users\boa65\Downloads\renpy-6.99.14.3-sdk\renpy\ast.py", line 1729, in execute
    if renpy.python.py_eval(condition):
  File "C:\Users\boa65\Downloads\renpy-6.99.14.3-sdk\renpy\python.py", line 1919, in py_eval
    return py_eval_bytecode(code, globals, locals)
  File "C:\Users\boa65\Downloads\renpy-6.99.14.3-sdk\renpy\python.py", line 1912, in py_eval_bytecode
    return eval(bytecode, globals, locals)
  File "game/script.rpy", line 303, in <module>
    if dic["ch03_1plyr"] == "positive":
KeyError: u'ch03_1plyr'

Windows-8-6.2.9200
Ren'Py 6.99.14.3.3347
re-late 1.0
Mon May 07 23:04:55 2018
